#VRML_SIM R2021a utf8
WorldInfo {
  coordinateSystem "NUE"
  contactProperties [
    ContactProperties {
    }
  ]
}
Viewpoint {
  orientation 0.8292934290066514 -0.5113791711236697 -0.22530812667824152 5.306466671413418
  position -0.9188962263033108 1.000253603370941 -0.24985147580430225
}
Background {
  skyColor [
    1 1 1
  ]
}
DEF Floor Solid {
  translation 0 0.09 0
  children [
    DEF Floor Shape {
      appearance PBRAppearance {
        baseColor 0 0.333333 0
        metalness 0
      }
      geometry Box {
        size 5 0.1 5
      }
    }
  ]
  name "solid(1)"
  boundingObject USE Floor
}
Robot {
  translation -1.2 0.19 -1.08
  children [
    Camera {
      translation 0 0.01 0.1
      rotation 0 -1 0 -3.1415853071795863
      scale 0.3 0.3 0.3
      children [
        DEF cam Shape {
          appearance PBRAppearance {
            baseColor 0 0.494118 0.741176
            metalness 0.6
          }
          geometry Sphere {
            radius 0.04
            subdivision 5
          }
        }
      ]
      name "cam"
      boundingObject USE cam
      physics Physics {
      }
    }
    DistanceSensor {
      translation 0.02 0 0.1
      rotation 0 1 0 -1.27
      scale 0.06 0.06 0.06
      children [
        DEF DS Shape {
          appearance PBRAppearance {
            baseColor 0.333333 0 0
            metalness 0.4
          }
          geometry Box {
            size 0.1 0.1 0.1
          }
        }
      ]
      name "ds_right"
      boundingObject USE DS
      physics Physics {
      }
    }
    DistanceSensor {
      translation -0.02 0 0.1
      rotation 0 1 0 -1.87
      scale 0.06 0.06 0.06
      children [
        DEF DS Shape {
          appearance PBRAppearance {
            baseColor 0.333333 0 0
            metalness 0.4
          }
          geometry Box {
            size 0.1 0.1 0.1
          }
        }
      ]
      name "ds_left"
      boundingObject USE DS
      physics Physics {
      }
    }
    HingeJoint {
      jointParameters HingeJointParameters {
        anchor 0.06 -0.01 0.05
      }
      device [
        RotationalMotor {
          name "wheel1"
        }
      ]
      endPoint Solid {
        translation 0.06 -0.01 0.05
        rotation -1.3154763129257598e-15 -2.159737230176621e-16 1 1.5699999999999987
        children [
          DEF Wheel Shape {
            appearance PBRAppearance {
              baseColor 0.866667 0.866667 0.866667
              metalness 0.3
            }
            geometry Cylinder {
              height 0.02
              radius 0.04
            }
          }
        ]
        name "wheel1"
        boundingObject USE Wheel
        physics Physics {
        }
      }
    }
    HingeJoint {
      jointParameters HingeJointParameters {
        anchor -0.06 -0.01 0.05
      }
      device [
        RotationalMotor {
          name "wheel2"
        }
      ]
      endPoint Solid {
        translation -0.06 -0.01 0.05
        rotation -4.319474460353244e-16 -1.9633974819787472e-17 1 1.5699999999999972
        children [
          DEF Wheel Shape {
            appearance PBRAppearance {
              baseColor 0.866667 0.866667 0.866667
              metalness 0.3
            }
            geometry Cylinder {
              height 0.02
              radius 0.04
            }
          }
        ]
        name "wheel2"
        boundingObject USE Wheel
        physics Physics {
          centerOfMass [
            0 0 0
          ]
        }
      }
    }
    HingeJoint {
      jointParameters HingeJointParameters {
        anchor 0.06 -0.01 -0.05
      }
      device [
        RotationalMotor {
          name "wheel3"
        }
      ]
      endPoint Solid {
        translation 0.06 -0.01 -0.05
        rotation -8.049929676112858e-16 -2.5524167265723697e-16 1 1.569999999999999
        children [
          DEF Wheel Shape {
            appearance PBRAppearance {
              baseColor 0.866667 0.866667 0.866667
              metalness 0.3
            }
            geometry Cylinder {
              height 0.02
              radius 0.04
            }
          }
        ]
        name "wheel3"
        boundingObject USE Wheel
        physics Physics {
        }
      }
    }
    HingeJoint {
      jointParameters HingeJointParameters {
        anchor -0.06 -0.01 -0.05
      }
      device [
        RotationalMotor {
          name "wheel4"
        }
      ]
      endPoint Solid {
        translation -0.06 -0.01 -0.05
        rotation 8.246269424310737e-16 -6.871891186925613e-17 1 1.5699999999999978
        children [
          DEF Wheel Shape {
            appearance PBRAppearance {
              baseColor 0.866667 0.866667 0.866667
              metalness 0.3
            }
            geometry Cylinder {
              height 0.02
              radius 0.04
            }
          }
        ]
        name "wheel4"
        boundingObject USE Wheel
        physics Physics {
        }
      }
    }
    DEF Body Shape {
      appearance PBRAppearance {
        baseColor 0.329412 0.329412 0.329412
        metalness 0.5
      }
      geometry Box {
        size 0.1 0.05 0.2
      }
    }
  ]
  boundingObject USE Body
  physics Physics {
    centerOfMass [
      0 0 0
    ]
  }
  controller "cse461controller"
}
DEF wall_1 Solid {
  translation 0 0.3 2.46
  children [
    DEF wall1 Shape {
      appearance Appearance {
        material Material {
          diffuseColor 0.0666667 0.0823529 0.152941
        }
      }
      geometry Box {
        size 5 0.5 0.1
      }
    }
  ]
  name "wall1"
  boundingObject USE wall1
}
DEF wall_2 Solid {
  translation 0 0.29 -2.48
  children [
    DEF wall2 Shape {
      appearance Appearance {
        material Material {
          diffuseColor 0.0666667 0.0823529 0.152941
        }
      }
      geometry Box {
        size 5 0.5 0.1
      }
    }
  ]
  name "wall2"
  boundingObject USE wall2
}
DEF wall_3 Solid {
  translation 2.46 0.3 -9.03567e-06
  rotation 0 1 0 1.5708
  children [
    DEF wall3 Shape {
      appearance Appearance {
        material Material {
          diffuseColor 0.0666667 0.0823529 0.152941
        }
      }
      geometry Box {
        size 5 0.5 0.1
      }
    }
  ]
  name "wall3"
  boundingObject USE wall3
}
DEF wall_4 Solid {
  translation -2.47 0.29 9.07293e-06
  rotation 0 1 0 1.5708
  children [
    DEF wall4 Shape {
      appearance Appearance {
        material Material {
          diffuseColor 0.0666667 0.0823529 0.152941
        }
      }
      geometry Box {
        size 5 0.5 0.1
      }
    }
  ]
  name "wall4"
  boundingObject USE wall4
}
DirectionalLight {
  direction 0 -1 -0.6
  intensity 3
  castShadows TRUE
}
DEF Cylinder Solid {
  translation 0.12 0.39 0.46
  children [
    DEF cylinder Shape {
      appearance Appearance {
        material Material {
          diffuseColor 0.333333 0 0
        }
      }
      geometry Cylinder {
        height 0.5
        radius 0.1
        subdivision 24
      }
    }
  ]
  name "cone"
  boundingObject USE cylinder
  physics Physics {
    centerOfMass [
      0 0 0
    ]
  }
}
DEF cone Solid {
  translation -1.24 0.39 0.89
  children [
    DEF cone Shape {
      appearance PBRAppearance {
        baseColor 0 0.952941 0.952941
        metalness 0
      }
      geometry Cone {
        bottomRadius 0.2
        height 0.5
        subdivision 36
      }
    }
  ]
  boundingObject Group {
    children [
      DEF cylinder1 Transform {
        translation 0 -0.05 0
        children [
          Shape {
            appearance PBRAppearance {
              metalness 0
            }
            geometry Cylinder {
              height 0.4
              radius 0.2
              subdivision 80
            }
          }
        ]
      }
      DEF cylinder2 Transform {
        translation 0 0.13 0
        children [
          Shape {
            appearance PBRAppearance {
              metalness 0
            }
            geometry Cylinder {
              height 0.2
              radius 0.1
              subdivision 80
            }
          }
        ]
      }
    ]
  }
  physics Physics {
    centerOfMass [
      0 0 0
    ]
  }
}
DEF sphere Solid {
  translation 1.3 0.46 0.35
  children [
    DEF sphere Shape {
      appearance Appearance {
        material Material {
          diffuseColor 0.666667 0.333333 0
        }
      }
      geometry Sphere {
        radius 0.3
        subdivision 5
      }
    }
  ]
  name "sphere"
  boundingObject USE sphere
  physics Physics {
    density 100
    centerOfMass [
      0 0 0
    ]
  }
}
Robot {
  translation 0.00237073 0.3 -0.97
  scale 4 4 4
  children [
    DistanceSensor {
      translation 0.02 0 0.1
      rotation 0 -1 0 1.27
      children [
        DEF ds_right Shape {
          appearance PBRAppearance {
            baseColor 1 0.666667 0
          }
          geometry Box {
            size 0.01 0.01 0.01
          }
        }
      ]
      name "ds_right"
      boundingObject USE ds_right
      physics Physics {
      }
    }
    DistanceSensor {
      translation -0.02 0 0.1
      rotation 0 -1 0 1.87
      children [
        DEF ds_left Shape {
          appearance PBRAppearance {
            baseColor 1 0.666667 0
          }
          geometry Box {
            size 0.01 0.01 0.01
          }
        }
      ]
      name "ds_left"
      boundingObject USE ds_left
      physics Physics {
      }
    }
    HingeJoint {
      jointParameters HingeJointParameters {
        anchor 0.06000000000000003 -3.185898102515203e-26 0.05999999999999997
      }
      device [
        RotationalMotor {
          name "wheel1"
        }
      ]
      endPoint Solid {
        translation 0.06000000000000003 -3.185898102515203e-26 0.05999999999999997
        rotation -5.74400375962057e-10 5.739432577603027e-10 1 1.5699999999999903
        children [
          DEF robot_wheel Shape {
            appearance PBRAppearance {
              baseColor 0.333333 0 0
              metalness 0
            }
            geometry Cylinder {
              height 0.02
              radius 0.04
              subdivision 24
            }
            castShadows FALSE
          }
        ]
        boundingObject USE robot_wheel
        physics Physics {
          centerOfMass [
            0 0 0
          ]
        }
      }
    }
    HingeJoint {
      jointParameters HingeJointParameters {
        anchor -0.060000000000000116 -7.105427350677355e-15 0.05999999999999997
      }
      device [
        RotationalMotor {
          name "wheel2"
        }
      ]
      endPoint Solid {
        translation -0.060000000000000116 -7.105427350677355e-15 0.05999999999999997
        rotation -1.0413255125311371e-09 1.0404974300091375e-09 1 1.5699999999999898
        children [
          DEF robot_wheel Shape {
            appearance PBRAppearance {
              baseColor 0.333333 0 0
              metalness 0
            }
            geometry Cylinder {
              height 0.02
              radius 0.04
              subdivision 24
            }
            castShadows FALSE
          }
        ]
        name "solid(1)"
        boundingObject USE robot_wheel
        physics Physics {
          centerOfMass [
            0 0 0
          ]
        }
      }
    }
    HingeJoint {
      jointParameters HingeJointParameters {
        anchor 0.06000000000000003 -2.0451779053526535e-24 -0.05999999999999986
      }
      device [
        RotationalMotor {
          name "wheel3"
        }
      ]
      endPoint Solid {
        translation 0.06000000000000003 -2.0451779053526535e-24 -0.05999999999999986
        rotation 7.374375768702383e-09 -7.3685065846095036e-09 1 1.569999999999991
        children [
          DEF robot_wheel Shape {
            appearance PBRAppearance {
              baseColor 0.333333 0 0
              metalness 0
            }
            geometry Cylinder {
              height 0.02
              radius 0.04
              subdivision 24
            }
            castShadows FALSE
          }
        ]
        name "solid(2)"
        boundingObject USE robot_wheel
        physics Physics {
          centerOfMass [
            0 0 0
          ]
        }
      }
    }
    HingeJoint {
      jointParameters HingeJointParameters {
        anchor -0.060000000000000095 -8.243875234196938e-25 -0.05999999999999997
      }
      device [
        RotationalMotor {
          name "wheel4"
        }
      ]
      endPoint Solid {
        translation -0.060000000000000095 -8.243875234196938e-25 -0.05999999999999997
        rotation 1.4862649953124105e-08 -1.4850819226720796e-08 0.9999999999999998 1.5699999999999947
        children [
          DEF robot_wheel Shape {
            appearance PBRAppearance {
              baseColor 0.333333 0 0
              metalness 0
            }
            geometry Cylinder {
              height 0.02
              radius 0.04
              subdivision 24
            }
            castShadows FALSE
          }
        ]
        name "solid(3)"
        boundingObject USE robot_wheel
        physics Physics {
          centerOfMass [
            0 0 0
          ]
        }
      }
    }
    DEF body Shape {
      appearance PBRAppearance {
        baseColor 0.666667 0 0.498039
        metalness 0
      }
      geometry Box {
        size 0.1 0.05 0.2
      }
    }
  ]
  boundingObject USE body
  physics Physics {
    density 100
    centerOfMass [
      0 0 0
    ]
  }
  controller "cse461controller"
}
